<mujoco model="Gripper-with-LEGO-tray">

  <!-- 场景、机器人 -->
  <include file="scene.xml"/>

    <!-- <include file="g2.xml"/> -->
  <asset>
    <mesh name="base_link" file="base_link.STL"/>
    <mesh name="left_link" file="left_link.STL"/>
    <mesh name="right_link" file="right_link.STL"/>
    <material name="matplane" reflectance="0." texture="texplane1" texrepeat="1 1" texuniform="true" />
    <material name="visualgeom" rgba="0.5 0.9 0.2 1" />
  </asset>

  <default>
    <joint limited="true" damping="0.01" armature="0.01" frictionloss="0.001" />
    <geom condim="4" contype="1" conaffinity="15" friction="0.9 0.2 0.2" solref="0.001 2" />
    <motor ctrllimited="true" />
    <equality solref="0.001 2" />
    <default class="visualgeom">
      <geom material="visualgeom" condim="1" contype="0" conaffinity="0" />
    </default>
  </default>
  <!-- SDF 求解参数 -->
  <option cone="elliptic" impratio="10" integrator="implicitfast"
          sdf_iterations="50" sdf_initpoints="40" ccd_iterations="100"
          timestep="0.001"/>

  <!--  sdflib -->
  <extension>
    <plugin plugin="mujoco.sdf.sdflib">
      <instance name="sdflego">
        <config key="aabb" value="0"/>
      </instance>
    </plugin>
  </extension>

  <asset>
    <mesh name="lego" file="../lego.obj" scale="0.01 0.01 0.01">
      <plugin instance="sdflego"/>
    </mesh>
  </asset>
  
  <default>
    <geom solimp="0.99 0.999 0.0001" solref="0.002 1" friction="0.8 0.01 0.001"/>
  </default>

  <worldbody>

    <!-- 托盘 -->
    <body name="tray" pos="0 0 0">
      <geom name="tray_floor" type="box" size="0.20 0.20 0.005"
            pos="0 0 0.005" rgba="0.7 0.7 0.7 1" contype="1" conaffinity="1"/>
      <geom name="tray_wall_xpos" type="box" size="0.005 0.20 0.02"
            pos="0.205 0 0.03" rgba="0.6 0.6 0.6 1"/>
      <geom name="tray_wall_xneg" type="box" size="0.005 0.20 0.02"
            pos="-0.205 0 0.03" rgba="0.6 0.6 0.6 1"/>
      <geom name="tray_wall_ypos" type="box" size="0.20 0.005 0.02"
            pos="0 0.205 0.03" rgba="0.6 0.6 0.6 1"/>
      <geom name="tray_wall_yneg" type="box" size="0.20 0.005 0.02"
            pos="0 -0.205 0.03" rgba="0.6 0.6 0.6 1"/>
    </body>

    <!-- g2 -->

  <body name="palm" pos="0 0 0.5">
    <joint name="x"    type="slide" axis="1 0 0" range="-0.25 0.25"/>
    <joint name="y"    type="slide" axis="0 1 0" range="-0.25 0.25"/>
    <joint name="lift" type="slide" axis="0 0 1" range="-0.5 0.50"/>
    <joint name="yaw"  type="hinge" axis="0 0 1" range="-3.1416 3.1416"/>

    <geom type="box" size="0.1 0.1 0.01" rgba="0.2 0.2 0.8 0.5"/>
      <body name="base" pos="0 0 0" quat="0 1 0 0">

        <site name="imu" size="0.01" pos="0 0 0" />
        <geom type="mesh" rgba="0.75294 0.75294 0.75294 1" mesh="base_link" contype="1" conaffinity="0"  group="1" class="visualgeom" />
        <geom type="mesh" rgba="0.75294 0.75294 0.75294 1" mesh="base_link" />
        <body name="left_link" pos="0 0 0.0635" quat="0.707105 0 -0.707108 0">
          <inertial pos="0.018307 5.9636e-06 0.012505" quat="0 0.798204 0 0.602388" mass="0.054004" diaginertia="5.10732e-05 4.78e-05 2.24468e-05" />
          <joint name="left_joint" pos="0 0 0" axis="0 0 1" type="slide" range="0 0.0166" />
          <geom type="mesh" rgba="0.75294 0.75294 0.75294 1" mesh="left_link" contype="1" conaffinity="0"  group="1" class="visualgeom" />
          <geom type="mesh" rgba="0.75294 0.75294 0.75294 1" mesh="left_link" />
        </body>
        <body name="right_link" pos="0 0 0.0635" quat="-2.59734e-06 0.707105 2.59735e-06 0.707108">
          <inertial pos="0.018307 -6.8572e-07 0.012505" quat="0 0.798204 0 0.602388" mass="0.054004" diaginertia="5.10732e-05 4.78e-05 2.24468e-05" />
          <joint name="right_joint" pos="0 0 0" axis="0 0 1" type="slide" range="0 0.0166" />
          <geom type="mesh" rgba="0.75294 0.75294 0.75294 1" mesh="right_link" contype="1" conaffinity="0"  group="1" class="visualgeom" />
          <geom type="mesh" rgba="0.75294 0.75294 0.75294 1" mesh="right_link" />
        </body>
      </body>
  </body>
      <body name="lego_00" pos="-0.12 -0.06 0.2">
        <freejoint/>
        <inertial pos="0 0 0" mass="0.02" diaginertia="1e-6 1e-6 1e-6"/>

        <geom type="sdf" name="lego_00_geom"  friction="2.0 0.01 0.00001" mesh="lego"  rgba="0.9 0.3 0.1 1">

          <plugin instance="sdflego"/>
        </geom>
      </body>
      <body name="lego_01" pos="-0.06 -0.06 0.28">
        <freejoint/>
        <geom type="sdf" name="lego_01_geom" friction="2.0 0.01 0.00001"  mesh="lego"  rgba="0.9 0.6 0.1 1">
          <plugin instance="sdflego"/>
        </geom>
      </body>
      <body name="lego_02" pos="0.00 -0.06 0.29">
        <freejoint/>
        <inertial pos="0 0 0" mass="0.02" diaginertia="1e-6 1e-6 1e-6"/>

        <geom type="sdf" name="lego_02_geom"  friction="2.0 0.01 0.00001" mesh="lego" rgba="0.2 0.7 0.2 1">
          <plugin instance="sdflego"/>
        </geom>
      </body>
      <body name="lego_03" pos="0.06 -0.06 0.18">
        <freejoint/>
        <inertial pos="0 0 0" mass="0.02" diaginertia="1e-6 1e-6 1e-6"/>

        <geom type="sdf" name="lego_03_geom" friction="2.0 0.01 0.00001" mesh="lego"  rgba="0.2 0.5 0.9 1">
          <plugin instance="sdflego"/>
        </geom>
      </body>
      <body name="lego_04" pos="0.12 -0.06 0.09">
        <freejoint/>
        <inertial pos="0 0 0" mass="0.02" diaginertia="1e-6 1e-6 1e-6"/>

        <geom type="sdf" name="lego_04_geom"  friction="2.0 0.01 0.0001" mesh="lego"  rgba="0.6 0.3 0.9 1">
          <plugin instance="sdflego"/>
        </geom>
      </body>

      <!-- 第 2 行 (y=+0.06) -->
      <body name="lego_05" pos="-0.12 0.06 0.13">
        <freejoint/>
        <inertial pos="0 0 0" mass="0.02" diaginertia="1e-6 1e-6 1e-6"/>

        <geom type="sdf" name="lego_05_geom"  friction="2.0 0.01 0.00001" mesh="lego"  rgba="0.9 0.3 0.1 1">
          <plugin instance="sdflego"/>
        </geom>
      </body>
      <body name="lego_06" pos="-0.06 0.06 0.3">
        <freejoint/>
        <inertial pos="0 0 0" mass="0.02" diaginertia="1e-6 1e-6 1e-6"/>

        <geom type="sdf" name="lego_06_geom" friction="2.0 0.01 0.00001" mesh="lego"  rgba="0.9 0.6 0.1 1">
          <plugin instance="sdflego"/>
        </geom>
      </body>

    <body name="lego_07" pos="0.067 0.223 1.321">
      <freejoint/>
      <geom type="sdf" name="lego_07_geom" friction="2.0 0.01 0.00001" mesh="lego" rgba="0.5 0.5 0.1 1">
        <plugin instance="sdflego"/>
      </geom>
    </body>

    <body name="lego_08" pos="-0.045 -0.188 1.224">
      <freejoint/>
      <geom type="sdf" name="lego_08_geom" friction="2.0 0.01 0.00001" mesh="lego" rgba="0.1 0.8 0.8 1">
        <plugin instance="sdflego"/>
      </geom>
    </body>

    <body name="lego_09" pos="-0.258 0.270 1.163">
      <freejoint/>
      <geom type="sdf" name="lego_09_geom" friction="2.0 0.01 0.00001" mesh="lego" rgba="0.9 0.1 0.9 1">
        <plugin instance="sdflego"/>
      </geom>
    </body>

    <body name="lego_10" pos="0.166 0.060 1.229">
      <freejoint/>
      <geom type="sdf" name="lego_10_geom" friction="2.0 0.01 0.00001" mesh="lego" rgba="0.9 0.3 0.1 1">
        <plugin instance="sdflego"/>
      </geom>
    </body>

    <body name="lego_11" pos="0.182 -0.082 1.445">
      <freejoint/>
      <geom type="sdf" name="lego_11_geom" friction="2.0 0.01 0.00001" mesh="lego" rgba="0.9 0.6 0.1 1">
        <plugin instance="sdflego"/>
      </geom>
    </body>

 
    <body name="lego_012" pos="0.149 0.088 0.096">
      <freejoint/>
      <inertial pos="0 0 0" mass="0.02" diaginertia="1e-6 1e-6 1e-6"/>
      <geom type="sdf" name="lego_012_geom" 
            friction="2.0 0.01 0.00001" mesh="lego"  
            rgba="0.88 0.62 0.21 1">
        <plugin instance="sdflego"/>
      </geom>
    </body>
    

    <body name="lego_013" pos="0.055 -0.151 0.119">
      <freejoint/>
      <inertial pos="0 0 0" mass="0.02" diaginertia="1e-6 1e-6 1e-6"/>
      <geom type="sdf" name="lego_013_geom" 
            friction="2.0 0.01 0.00001" mesh="lego"  
            rgba="0.80 0.64 0.64 1">
        <plugin instance="sdflego"/>
      </geom>
    </body>
    

    <body name="lego_014" pos="-0.167 -0.051 0.123">
      <freejoint/>
      <inertial pos="0 0 0" mass="0.02" diaginertia="1e-6 1e-6 1e-6"/>
      <geom type="sdf" name="lego_014_geom" 
            friction="2.0 0.01 0.00001" mesh="lego"  
            rgba="0.32 0.64 0.62 1">
        <plugin instance="sdflego"/>
      </geom>
    </body>
    

    <body name="lego_015" pos="-0.058 0.091 0.143">
      <freejoint/>
      <inertial pos="0 0 0" mass="0.02" diaginertia="1e-6 1e-6 1e-6"/>
      <geom type="sdf" name="lego_015_geom" 
            friction="2.0 0.01 0.00001" mesh="lego"  
            rgba="0.13 0.48 0.17 1">
        <plugin instance="sdflego"/>
      </geom>
    </body>
    

    <body name="lego_016" pos="-0.102 0.083 0.122">
      <freejoint/>
      <inertial pos="0 0 0" mass="0.02" diaginertia="1e-6 1e-6 1e-6"/>
      <geom type="sdf" name="lego_016_geom" 
            friction="2.0 0.01 0.00001" mesh="lego"  
            rgba="0.25 0.89 0.87 1">
        <plugin instance="sdflego"/>
      </geom>
    </body>
    

    <body name="lego_017" pos="0.137 0.113 0.125">
      <freejoint/>
      <inertial pos="0 0 0" mass="0.02" diaginertia="1e-6 1e-6 1e-6"/>
      <geom type="sdf" name="lego_017_geom" 
            friction="2.0 0.01 0.00001" mesh="lego"  
            rgba="0.67 0.31 0.58 1">
        <plugin instance="sdflego"/>
      </geom>
    </body>
    

    <body name="lego_018" pos="-0.146 0.119 0.132">
      <freejoint/>
      <inertial pos="0 0 0" mass="0.02" diaginertia="1e-6 1e-6 1e-6"/>
      <geom type="sdf" name="lego_018_geom" 
            friction="2.0 0.01 0.00001" mesh="lego"  
            rgba="0.10 0.07 0.68 1">
        <plugin instance="sdflego"/>
      </geom>
    </body>
    

    <body name="lego_019" pos="0.177 0.023 0.094">
      <freejoint/>
      <inertial pos="0 0 0" mass="0.02" diaginertia="1e-6 1e-6 1e-6"/>
      <geom type="sdf" name="lego_019_geom" 
            friction="2.0 0.01 0.00001" mesh="lego"  
            rgba="0.61 0.94 0.92 1">
        <plugin instance="sdflego"/>
      </geom>
    </body>
    

    <body name="lego_020" pos="0.160 0.114 0.093">
      <freejoint/>
      <inertial pos="0 0 0" mass="0.02" diaginertia="1e-6 1e-6 1e-6"/>
      <geom type="sdf" name="lego_020_geom" 
            friction="2.0 0.01 0.00001" mesh="lego"  
            rgba="0.27 0.04 0.94 1">
        <plugin instance="sdflego"/>
      </geom>
    </body>
    

    <body name="lego_021" pos="-0.167 -0.043 0.100">
      <freejoint/>
      <inertial pos="0 0 0" mass="0.02" diaginertia="1e-6 1e-6 1e-6"/>
      <geom type="sdf" name="lego_021_geom" 
            friction="2.0 0.01 0.00001" mesh="lego"  
            rgba="0.02 0.11 0.64 1">
        <plugin instance="sdflego"/>
      </geom>
    </body>
    

    <body name="lego_022" pos="0.143 -0.091 0.135">
      <freejoint/>
      <inertial pos="0 0 0" mass="0.02" diaginertia="1e-6 1e-6 1e-6"/>
      <geom type="sdf" name="lego_022_geom" 
            friction="2.0 0.01 0.00001" mesh="lego"  
            rgba="0.27 0.22 0.26 1">
        <plugin instance="sdflego"/>
      </geom>
    </body>
    

    <body name="lego_023" pos="-0.102 0.052 0.148">
      <freejoint/>
      <inertial pos="0 0 0" mass="0.02" diaginertia="1e-6 1e-6 1e-6"/>
      <geom type="sdf" name="lego_023_geom" 
            friction="2.0 0.01 0.00001" mesh="lego"  
            rgba="0.81 0.54 0.94 1">
        <plugin instance="sdflego"/>
      </geom>
    </body>
    

    <body name="lego_024" pos="-0.004 0.156 0.142">
      <freejoint/>
      <inertial pos="0 0 0" mass="0.02" diaginertia="1e-6 1e-6 1e-6"/>
      <geom type="sdf" name="lego_024_geom" 
            friction="2.0 0.01 0.00001" mesh="lego"  
            rgba="0.26 0.58 0.77 1">
        <plugin instance="sdflego"/>
      </geom>
    </body>
    

    <body name="lego_025" pos="-0.105 -0.129 0.115">
      <freejoint/>
      <inertial pos="0 0 0" mass="0.02" diaginertia="1e-6 1e-6 1e-6"/>
      <geom type="sdf" name="lego_025_geom" 
            friction="2.0 0.01 0.00001" mesh="lego"  
            rgba="0.35 0.49 0.45 1">
        <plugin instance="sdflego"/>
      </geom>
    </body>
    

    <body name="lego_026" pos="-0.004 0.166 0.060">
      <freejoint/>
      <inertial pos="0 0 0" mass="0.02" diaginertia="1e-6 1e-6 1e-6"/>
      <geom type="sdf" name="lego_026_geom" 
            friction="2.0 0.01 0.00001" mesh="lego"  
            rgba="0.90 0.39 0.42 1">
        <plugin instance="sdflego"/>
      </geom>
    </body>
    

    <body name="lego_027" pos="-0.072 -0.138 0.110">
      <freejoint/>
      <inertial pos="0 0 0" mass="0.02" diaginertia="1e-6 1e-6 1e-6"/>
      <geom type="sdf" name="lego_027_geom" 
            friction="2.0 0.01 0.00001" mesh="lego"  
            rgba="0.06 0.00 0.30 1">
        <plugin instance="sdflego"/>
      </geom>
    </body>
    

    <body name="lego_028" pos="-0.038 0.150 0.129">
      <freejoint/>
      <inertial pos="0 0 0" mass="0.02" diaginertia="1e-6 1e-6 1e-6"/>
      <geom type="sdf" name="lego_028_geom" 
            friction="2.0 0.01 0.00001" mesh="lego"  
            rgba="0.52 0.71 0.49 1">
        <plugin instance="sdflego"/>
      </geom>
    </body>
    

    <body name="lego_029" pos="0.116 0.070 0.098">
      <freejoint/>
      <inertial pos="0 0 0" mass="0.02" diaginertia="1e-6 1e-6 1e-6"/>
      <geom type="sdf" name="lego_029_geom" 
            friction="2.0 0.01 0.00001" mesh="lego"  
            rgba="0.63 0.73 0.68 1">
        <plugin instance="sdflego"/>
      </geom>
    </body>
    

    <body name="lego_030" pos="-0.025 0.122 0.057">
      <freejoint/>
      <inertial pos="0 0 0" mass="0.02" diaginertia="1e-6 1e-6 1e-6"/>
      <geom type="sdf" name="lego_030_geom" 
            friction="2.0 0.01 0.00001" mesh="lego"  
            rgba="0.57 0.63 0.30 1">
        <plugin instance="sdflego"/>
      </geom>
    </body>
    

    <body name="lego_031" pos="0.073 0.077 0.128">
      <freejoint/>
      <inertial pos="0 0 0" mass="0.02" diaginertia="1e-6 1e-6 1e-6"/>
      <geom type="sdf" name="lego_031_geom" 
            friction="2.0 0.01 0.00001" mesh="lego"  
            rgba="0.16 0.69 0.81 1">
        <plugin instance="sdflego"/>
      </geom>
    </body>
    

    <body name="lego_032" pos="-0.108 0.154 0.144">
      <freejoint/>
      <inertial pos="0 0 0" mass="0.02" diaginertia="1e-6 1e-6 1e-6"/>
      <geom type="sdf" name="lego_032_geom" 
            friction="2.0 0.01 0.00001" mesh="lego"  
            rgba="0.10 0.46 0.41 1">
        <plugin instance="sdflego"/>
      </geom>
    </body>
    

    <body name="lego_033" pos="0.094 -0.138 0.120">
      <freejoint/>
      <inertial pos="0 0 0" mass="0.02" diaginertia="1e-6 1e-6 1e-6"/>
      <geom type="sdf" name="lego_033_geom" 
            friction="2.0 0.01 0.00001" mesh="lego"  
            rgba="0.34 0.37 0.35 1">
        <plugin instance="sdflego"/>
      </geom>
    </body>
    

    <body name="lego_034" pos="-0.058 0.154 0.133">
      <freejoint/>
      <inertial pos="0 0 0" mass="0.02" diaginertia="1e-6 1e-6 1e-6"/>
      <geom type="sdf" name="lego_034_geom" 
            friction="2.0 0.01 0.00001" mesh="lego"  
            rgba="0.06 0.37 0.03 1">
        <plugin instance="sdflego"/>
      </geom>
    </body>
    

    <body name="lego_035" pos="0.063 -0.165 0.101">
      <freejoint/>
      <inertial pos="0 0 0" mass="0.02" diaginertia="1e-6 1e-6 1e-6"/>
      <geom type="sdf" name="lego_035_geom" 
            friction="2.0 0.01 0.00001" mesh="lego"  
            rgba="0.21 0.02 0.35 1">
        <plugin instance="sdflego"/>
      </geom>
    </body>
    

    <body name="lego_036" pos="-0.021 0.010 0.092">
      <freejoint/>
      <inertial pos="0 0 0" mass="0.02" diaginertia="1e-6 1e-6 1e-6"/>
      <geom type="sdf" name="lego_036_geom" 
            friction="2.0 0.01 0.00001" mesh="lego"  
            rgba="0.51 0.05 0.32 1">
        <plugin instance="sdflego"/>
      </geom>
    </body>
    

    <body name="lego_037" pos="-0.136 0.075 0.060">
      <freejoint/>
      <inertial pos="0 0 0" mass="0.02" diaginertia="1e-6 1e-6 1e-6"/>
      <geom type="sdf" name="lego_037_geom" 
            friction="2.0 0.01 0.00001" mesh="lego"  
            rgba="0.94 0.74 0.75 1">
        <plugin instance="sdflego"/>
      </geom>
    </body>
    

    <body name="lego_038" pos="-0.120 -0.177 0.078">
      <freejoint/>
      <inertial pos="0 0 0" mass="0.02" diaginertia="1e-6 1e-6 1e-6"/>
      <geom type="sdf" name="lego_038_geom" 
            friction="2.0 0.01 0.00001" mesh="lego"  
            rgba="0.88 0.55 0.19 1">
        <plugin instance="sdflego"/>
      </geom>
    </body>
    

    <body name="lego_039" pos="-0.032 -0.008 0.147">
      <freejoint/>
      <inertial pos="0 0 0" mass="0.02" diaginertia="1e-6 1e-6 1e-6"/>
      <geom type="sdf" name="lego_039_geom" 
            friction="2.0 0.01 0.00001" mesh="lego"  
            rgba="0.41 0.13 0.22 1">
        <plugin instance="sdflego"/>
      </geom>
    </body>
    

    <body name="lego_040" pos="-0.078 -0.141 0.075">
      <freejoint/>
      <inertial pos="0 0 0" mass="0.02" diaginertia="1e-6 1e-6 1e-6"/>
      <geom type="sdf" name="lego_040_geom" 
            friction="2.0 0.01 0.00001" mesh="lego"  
            rgba="0.54 0.04 0.29 1">
        <plugin instance="sdflego"/>
      </geom>
    </body>
    

    <body name="lego_041" pos="-0.073 -0.143 0.133">
      <freejoint/>
      <inertial pos="0 0 0" mass="0.02" diaginertia="1e-6 1e-6 1e-6"/>
      <geom type="sdf" name="lego_041_geom" 
            friction="2.0 0.01 0.00001" mesh="lego"  
            rgba="0.22 0.94 0.83 1">
        <plugin instance="sdflego"/>
      </geom>
    </body>
    

    <body name="lego_042" pos="-0.088 0.044 0.064">
      <freejoint/>
      <inertial pos="0 0 0" mass="0.02" diaginertia="1e-6 1e-6 1e-6"/>
      <geom type="sdf" name="lego_042_geom" 
            friction="2.0 0.01 0.00001" mesh="lego"  
            rgba="0.70 0.16 0.74 1">
        <plugin instance="sdflego"/>
      </geom>
    </body>
    

    <body name="lego_043" pos="0.029 0.049 0.070">
      <freejoint/>
      <inertial pos="0 0 0" mass="0.02" diaginertia="1e-6 1e-6 1e-6"/>
      <geom type="sdf" name="lego_043_geom" 
            friction="2.0 0.01 0.00001" mesh="lego"  
            rgba="0.11 0.58 0.01 1">
        <plugin instance="sdflego"/>
      </geom>
    </body>
    

    <body name="lego_044" pos="0.088 -0.157 0.070">
      <freejoint/>
      <inertial pos="0 0 0" mass="0.02" diaginertia="1e-6 1e-6 1e-6"/>
      <geom type="sdf" name="lego_044_geom" 
            friction="2.0 0.01 0.00001" mesh="lego"  
            rgba="0.37 0.48 0.27 1">
        <plugin instance="sdflego"/>
      </geom>
    </body>
    

    <body name="lego_045" pos="0.038 -0.065 0.062">
      <freejoint/>
      <inertial pos="0 0 0" mass="0.02" diaginertia="1e-6 1e-6 1e-6"/>
      <geom type="sdf" name="lego_045_geom" 
            friction="2.0 0.01 0.00001" mesh="lego"  
            rgba="0.99 0.97 0.55 1">
        <plugin instance="sdflego"/>
      </geom>
    </body>
    

    <body name="lego_046" pos="-0.092 0.002 0.130">
      <freejoint/>
      <inertial pos="0 0 0" mass="0.02" diaginertia="1e-6 1e-6 1e-6"/>
      <geom type="sdf" name="lego_046_geom" 
            friction="2.0 0.01 0.00001" mesh="lego"  
            rgba="0.37 0.69 0.95 1">
        <plugin instance="sdflego"/>
      </geom>
    </body>
    

    <body name="lego_047" pos="0.068 -0.033 0.088">
      <freejoint/>
      <inertial pos="0 0 0" mass="0.02" diaginertia="1e-6 1e-6 1e-6"/>
      <geom type="sdf" name="lego_047_geom" 
            friction="2.0 0.01 0.00001" mesh="lego"  
            rgba="0.96 0.06 0.36 1">
        <plugin instance="sdflego"/>
      </geom>
    </body>
    

    <body name="lego_048" pos="-0.067 0.024 0.142">
      <freejoint/>
      <inertial pos="0 0 0" mass="0.02" diaginertia="1e-6 1e-6 1e-6"/>
      <geom type="sdf" name="lego_048_geom" 
            friction="2.0 0.01 0.00001" mesh="lego"  
            rgba="0.67 0.73 0.62 1">
        <plugin instance="sdflego"/>
      </geom>
    </body>
    

    <body name="lego_049" pos="0.072 0.095 0.148">
      <freejoint/>
      <inertial pos="0 0 0" mass="0.02" diaginertia="1e-6 1e-6 1e-6"/>
      <geom type="sdf" name="lego_049_geom" 
            friction="2.0 0.01 0.00001" mesh="lego"  
            rgba="0.36 0.89 0.97 1">
        <plugin instance="sdflego"/>
      </geom>
    </body>
    

    <body name="lego_050" pos="0.174 -0.002 0.147">
      <freejoint/>
      <inertial pos="0 0 0" mass="0.02" diaginertia="1e-6 1e-6 1e-6"/>
      <geom type="sdf" name="lego_050_geom" 
            friction="2.0 0.01 0.00001" mesh="lego"  
            rgba="0.19 0.20 0.07 1">
        <plugin instance="sdflego"/>
      </geom>
    </body>
    

    <body name="lego_051" pos="0.009 0.137 0.057">
      <freejoint/>
      <inertial pos="0 0 0" mass="0.02" diaginertia="1e-6 1e-6 1e-6"/>
      <geom type="sdf" name="lego_051_geom" 
            friction="2.0 0.01 0.00001" mesh="lego"  
            rgba="0.19 0.42 0.47 1">
        <plugin instance="sdflego"/>
      </geom>
    </body>
    

    <body name="lego_052" pos="0.012 0.079 0.085">
      <freejoint/>
      <inertial pos="0 0 0" mass="0.02" diaginertia="1e-6 1e-6 1e-6"/>
      <geom type="sdf" name="lego_052_geom" 
            friction="2.0 0.01 0.00001" mesh="lego"  
            rgba="0.02 0.94 0.95 1">
        <plugin instance="sdflego"/>
      </geom>
    </body>
    

    <body name="lego_053" pos="0.072 0.083 0.076">
      <freejoint/>
      <inertial pos="0 0 0" mass="0.02" diaginertia="1e-6 1e-6 1e-6"/>
      <geom type="sdf" name="lego_053_geom" 
            friction="2.0 0.01 0.00001" mesh="lego"  
            rgba="0.60 0.55 0.13 1">
        <plugin instance="sdflego"/>
      </geom>
    </body>
    

    <body name="lego_054" pos="0.074 -0.099 0.085">
      <freejoint/>
      <inertial pos="0 0 0" mass="0.02" diaginertia="1e-6 1e-6 1e-6"/>
      <geom type="sdf" name="lego_054_geom" 
            friction="2.0 0.01 0.00001" mesh="lego"  
            rgba="0.38 0.99 0.87 1">
        <plugin instance="sdflego"/>
      </geom>
    </body>
    

    <body name="lego_055" pos="0.107 -0.158 0.129">
      <freejoint/>
      <inertial pos="0 0 0" mass="0.02" diaginertia="1e-6 1e-6 1e-6"/>
      <geom type="sdf" name="lego_055_geom" 
            friction="2.0 0.01 0.00001" mesh="lego"  
            rgba="0.78 0.89 0.01 1">
        <plugin instance="sdflego"/>
      </geom>
    </body>
    

    <body name="lego_056" pos="-0.070 0.120 0.129">
      <freejoint/>
      <inertial pos="0 0 0" mass="0.02" diaginertia="1e-6 1e-6 1e-6"/>
      <geom type="sdf" name="lego_056_geom" 
            friction="2.0 0.01 0.00001" mesh="lego"  
            rgba="0.03 0.92 0.63 1">
        <plugin instance="sdflego"/>
      </geom>
    </body>
    

    <body name="lego_057" pos="0.115 -0.082 0.141">
      <freejoint/>
      <inertial pos="0 0 0" mass="0.02" diaginertia="1e-6 1e-6 1e-6"/>
      <geom type="sdf" name="lego_057_geom" 
            friction="2.0 0.01 0.00001" mesh="lego"  
            rgba="0.03 0.76 0.12 1">
        <plugin instance="sdflego"/>
      </geom>
    </body>
    

    <body name="lego_058" pos="0.091 0.136 0.134">
      <freejoint/>
      <inertial pos="0 0 0" mass="0.02" diaginertia="1e-6 1e-6 1e-6"/>
      <geom type="sdf" name="lego_058_geom" 
            friction="2.0 0.01 0.00001" mesh="lego"  
            rgba="0.66 0.97 0.54 1">
        <plugin instance="sdflego"/>
      </geom>
    </body>
    

    <body name="lego_059" pos="0.098 -0.116 0.116">
      <freejoint/>
      <inertial pos="0 0 0" mass="0.02" diaginertia="1e-6 1e-6 1e-6"/>
      <geom type="sdf" name="lego_059_geom" 
            friction="2.0 0.01 0.00001" mesh="lego"  
            rgba="0.65 0.69 0.01 1">
        <plugin instance="sdflego"/>
      </geom>
    </body>
    

    <body name="lego_060" pos="0.034 -0.153 0.116">
      <freejoint/>
      <inertial pos="0 0 0" mass="0.02" diaginertia="1e-6 1e-6 1e-6"/>
      <geom type="sdf" name="lego_060_geom" 
            friction="2.0 0.01 0.00001" mesh="lego"  
            rgba="0.61 0.44 0.90 1">
        <plugin instance="sdflego"/>
      </geom>
    </body>
    

    <body name="lego_061" pos="0.164 -0.020 0.132">
      <freejoint/>
      <inertial pos="0 0 0" mass="0.02" diaginertia="1e-6 1e-6 1e-6"/>
      <geom type="sdf" name="lego_061_geom" 
            friction="2.0 0.01 0.00001" mesh="lego"  
            rgba="0.41 0.89 0.25 1">
        <plugin instance="sdflego"/>
      </geom>
    </body>
    

    <body name="lego_062" pos="-0.082 -0.092 0.056">
      <freejoint/>
      <inertial pos="0 0 0" mass="0.02" diaginertia="1e-6 1e-6 1e-6"/>
      <geom type="sdf" name="lego_062_geom" 
            friction="2.0 0.01 0.00001" mesh="lego"  
            rgba="0.46 0.53 0.41 1">
        <plugin instance="sdflego"/>
      </geom>
    </body>
    

    <body name="lego_063" pos="-0.156 -0.141 0.116">
      <freejoint/>
      <inertial pos="0 0 0" mass="0.02" diaginertia="1e-6 1e-6 1e-6"/>
      <geom type="sdf" name="lego_063_geom" 
            friction="2.0 0.01 0.00001" mesh="lego"  
            rgba="0.42 0.46 0.55 1">
        <plugin instance="sdflego"/>
      </geom>
    </body>
    

    <body name="lego_064" pos="-0.108 0.004 0.092">
      <freejoint/>
      <inertial pos="0 0 0" mass="0.02" diaginertia="1e-6 1e-6 1e-6"/>
      <geom type="sdf" name="lego_064_geom" 
            friction="2.0 0.01 0.00001" mesh="lego"  
            rgba="0.03 0.35 0.77 1">
        <plugin instance="sdflego"/>
      </geom>
    </body>
    

    <body name="lego_065" pos="0.012 0.092 0.056">
      <freejoint/>
      <inertial pos="0 0 0" mass="0.02" diaginertia="1e-6 1e-6 1e-6"/>
      <geom type="sdf" name="lego_065_geom" 
            friction="2.0 0.01 0.00001" mesh="lego"  
            rgba="0.58 0.30 0.13 1">
        <plugin instance="sdflego"/>
      </geom>
    </body>
    

    <body name="lego_066" pos="0.032 -0.137 0.075">
      <freejoint/>
      <inertial pos="0 0 0" mass="0.02" diaginertia="1e-6 1e-6 1e-6"/>
      <geom type="sdf" name="lego_066_geom" 
            friction="2.0 0.01 0.00001" mesh="lego"  
            rgba="0.39 0.88 0.13 1">
        <plugin instance="sdflego"/>
      </geom>
    </body>
    

    <body name="lego_067" pos="-0.125 0.040 0.080">
      <freejoint/>
      <inertial pos="0 0 0" mass="0.02" diaginertia="1e-6 1e-6 1e-6"/>
      <geom type="sdf" name="lego_067_geom" 
            friction="2.0 0.01 0.00001" mesh="lego"  
            rgba="0.50 0.77 0.45 1">
        <plugin instance="sdflego"/>
      </geom>
    </body>
    

    <body name="lego_068" pos="0.060 0.003 0.064">
      <freejoint/>
      <inertial pos="0 0 0" mass="0.02" diaginertia="1e-6 1e-6 1e-6"/>
      <geom type="sdf" name="lego_068_geom" 
            friction="2.0 0.01 0.00001" mesh="lego"  
            rgba="0.87 0.06 0.51 1">
        <plugin instance="sdflego"/>
      </geom>
    </body>
    

    <body name="lego_069" pos="-0.091 -0.143 0.058">
      <freejoint/>
      <inertial pos="0 0 0" mass="0.02" diaginertia="1e-6 1e-6 1e-6"/>
      <geom type="sdf" name="lego_069_geom" 
            friction="2.0 0.01 0.00001" mesh="lego"  
            rgba="0.99 0.70 0.87 1">
        <plugin instance="sdflego"/>
      </geom>
    </body>
    


  </worldbody>

  <!-- 两侧手指对称 -->
  <equality>
    <joint joint1="right_joint" joint2="left_joint"/>
  </equality>

  <tendon>
    <fixed name="grasp">
      <joint joint="right_joint" coef="1"/>
      <joint joint="left_joint"  coef="1"/>
    </fixed>
  </tendon>
  <actuator>
    <motor name="left_joint" joint="left_joint" ctrllimited="true" ctrlrange="-1 1" gear="1" />
    <motor name="right_joint" joint="right_joint" ctrllimited="true" ctrlrange="-1 1" gear="1" />
    <position name="x"    joint="x" kp="800" dampratio="1" ctrlrange="-0.25 0.25"/>
    <position name="y"    joint="y" kp="800" dampratio="1" ctrlrange="-0.25 0.25"/>
    <position name="lift"  joint="lift"  kp="600" dampratio="1" ctrlrange="-0.5 0.5"/>
    <position name="rotation" joint="yaw" kp="400" dampratio="1" ctrlrange="-3.1416 3.1416"/>

  </actuator>

  <sensor>
    <actuatorpos name="left_joint_p" actuator="left_joint" />
    <actuatorvel name="left_joint_v" actuator="left_joint" />
    <actuatorfrc name="left_joint_f" actuator="left_joint" noise="0.001" />
    <actuatorpos name="right_joint_p" actuator="right_joint" />
    <actuatorvel name="right_joint_v" actuator="right_joint" />
    <actuatorfrc name="right_joint_f" actuator="right_joint" noise="0.001" />
    <framequat name="orientation" objtype="site" noise="0.001" objname="imu" />
    <gyro name="angular-velocity" site="imu" noise="0.005" cutoff="34.9" />
  </sensor>
</mujoco>

