<mujoco model="Gripper-with-LEGO-tray">

  <!-- 场景、机器人 -->
  <include file="scene.xml"/>

    <!-- <include file="g2.xml"/> -->
  <asset>
    <mesh name="base_link" file="base_link.STL"/>
    <mesh name="left_link" file="left_link.STL"/>
    <mesh name="right_link" file="right_link.STL"/>
    <material name="matplane" reflectance="0." texture="texplane1" texrepeat="1 1" texuniform="true" />
    <material name="visualgeom" rgba="0.5 0.9 0.2 1" />
  </asset>

  <default>
    <joint limited="true" damping="0.01" armature="0.01" frictionloss="0.001" />
    <geom condim="4" contype="1" conaffinity="15" friction="0.9 0.2 0.2" solref="0.001 2" />
    <motor ctrllimited="true" />
    <equality solref="0.001 2" />
    <default class="visualgeom">
      <geom material="visualgeom" condim="1" contype="0" conaffinity="0" />
    </default>
  </default>
  <!-- SDF 求解参数 -->
  <option cone="elliptic" impratio="10" integrator="implicitfast"
          sdf_iterations="50" sdf_initpoints="40" ccd_iterations="100"
          timestep="0.001"/>

  <!--  sdflib -->
  <extension>
    <plugin plugin="mujoco.sdf.sdflib">
      <instance name="sdflego">
        <config key="aabb" value="0"/>
      </instance>
    </plugin>
  </extension>

  <asset>
    <mesh name="lego" file="../lego.obj" scale="0.01 0.01 0.01">
      <plugin instance="sdflego"/>
    </mesh>
  </asset>
  
  <default>
    <geom solimp="0.99 0.999 0.0001" solref="0.002 1" friction="0.8 0.01 0.001"/>
  </default>

  <worldbody>

    <!-- 托盘 -->
    <body name="tray" pos="0 0 0">
      <geom name="tray_floor" type="box" size="0.20 0.20 0.005"
            pos="0 0 0.005" rgba="0.7 0.7 0.7 1" contype="1" conaffinity="1"/>
      <geom name="tray_wall_xpos" type="box" size="0.005 0.20 0.02"
            pos="0.205 0 0.03" rgba="0.6 0.6 0.6 1"/>
      <geom name="tray_wall_xneg" type="box" size="0.005 0.20 0.02"
            pos="-0.205 0 0.03" rgba="0.6 0.6 0.6 1"/>
      <geom name="tray_wall_ypos" type="box" size="0.20 0.005 0.02"
            pos="0 0.205 0.03" rgba="0.6 0.6 0.6 1"/>
      <geom name="tray_wall_yneg" type="box" size="0.20 0.005 0.02"
            pos="0 -0.205 0.03" rgba="0.6 0.6 0.6 1"/>
    </body>

    <!-- g2 -->

  <body name="palm" pos="0 0 0.5">
    <joint name="x"    type="slide" axis="1 0 0" range="-0.25 0.25"/>
    <joint name="y"    type="slide" axis="0 1 0" range="-0.25 0.25"/>
    <joint name="lift" type="slide" axis="0 0 1" range="-0.5 0.50"/>
    <joint name="yaw"  type="hinge" axis="0 0 1" range="-3.1416 3.1416"/>

    <geom type="box" size="0.1 0.1 0.01" rgba="0.2 0.2 0.8 0.5"/>
      <body name="base" pos="0 0 0" quat="0 1 0 0">

        <site name="imu" size="0.01" pos="0 0 0" />
        <geom type="mesh" rgba="0.75294 0.75294 0.75294 1" mesh="base_link" contype="1" conaffinity="0"  group="1" class="visualgeom" />
        <geom type="mesh" rgba="0.75294 0.75294 0.75294 1" mesh="base_link" />
        <body name="left_link" pos="0 0 0.0635" quat="0.707105 0 -0.707108 0">
          <inertial pos="0.018307 5.9636e-06 0.012505" quat="0 0.798204 0 0.602388" mass="0.054004" diaginertia="5.10732e-05 4.78e-05 2.24468e-05" />
          <joint name="left_joint" pos="0 0 0" axis="0 0 1" type="slide" range="0 0.0166" />
          <geom type="mesh" rgba="0.75294 0.75294 0.75294 1" mesh="left_link" contype="1" conaffinity="0"  group="1" class="visualgeom" />
          <geom type="mesh" rgba="0.75294 0.75294 0.75294 1" mesh="left_link" />
        </body>
        <body name="right_link" pos="0 0 0.0635" quat="-2.59734e-06 0.707105 2.59735e-06 0.707108">
          <inertial pos="0.018307 -6.8572e-07 0.012505" quat="0 0.798204 0 0.602388" mass="0.054004" diaginertia="5.10732e-05 4.78e-05 2.24468e-05" />
          <joint name="right_joint" pos="0 0 0" axis="0 0 1" type="slide" range="0 0.0166" />
          <geom type="mesh" rgba="0.75294 0.75294 0.75294 1" mesh="right_link" contype="1" conaffinity="0"  group="1" class="visualgeom" />
          <geom type="mesh" rgba="0.75294 0.75294 0.75294 1" mesh="right_link" />
        </body>
      </body>
  </body>
      <body name="lego_00" pos="-0.12 -0.06 0.2">
        <freejoint/>
        <inertial pos="0 0 0" mass="0.02" diaginertia="1e-6 1e-6 1e-6"/>

        <geom type="sdf" name="lego_00_geom"  friction="2.0 0.01 0.00001" mesh="lego"  rgba="0.9 0.3 0.1 1">

          <plugin instance="sdflego"/>
        </geom>
      </body>
      <body name="lego_01" pos="-0.06 -0.06 0.28">
        <freejoint/>
        <geom type="sdf" name="lego_01_geom" friction="2.0 0.01 0.00001"  mesh="lego"  rgba="0.9 0.6 0.1 1">
          <plugin instance="sdflego"/>
        </geom>
      </body>
      <body name="lego_02" pos="0.00 -0.06 0.29">
        <freejoint/>
        <inertial pos="0 0 0" mass="0.02" diaginertia="1e-6 1e-6 1e-6"/>

        <geom type="sdf" name="lego_02_geom"  friction="2.0 0.01 0.00001" mesh="lego" rgba="0.2 0.7 0.2 1">
          <plugin instance="sdflego"/>
        </geom>
      </body>
      <body name="lego_03" pos="0.06 -0.06 0.18">
        <freejoint/>
        <inertial pos="0 0 0" mass="0.02" diaginertia="1e-6 1e-6 1e-6"/>

        <geom type="sdf" name="lego_03_geom" friction="2.0 0.01 0.00001" mesh="lego"  rgba="0.2 0.5 0.9 1">
          <plugin instance="sdflego"/>
        </geom>
      </body>
      <body name="lego_04" pos="0.12 -0.06 0.09">
        <freejoint/>
        <inertial pos="0 0 0" mass="0.02" diaginertia="1e-6 1e-6 1e-6"/>

        <geom type="sdf" name="lego_04_geom"  friction="2.0 0.01 0.0001" mesh="lego"  rgba="0.6 0.3 0.9 1">
          <plugin instance="sdflego"/>
        </geom>
      </body>

      <!-- 第 2 行 (y=+0.06) -->
      <body name="lego_05" pos="-0.12 0.06 0.13">
        <freejoint/>
        <inertial pos="0 0 0" mass="0.02" diaginertia="1e-6 1e-6 1e-6"/>

        <geom type="sdf" name="lego_05_geom"  friction="2.0 0.01 0.00001" mesh="lego"  rgba="0.9 0.3 0.1 1">
          <plugin instance="sdflego"/>
        </geom>
      </body>
      <body name="lego_06" pos="-0.06 0.06 0.3">
        <freejoint/>
        <inertial pos="0 0 0" mass="0.02" diaginertia="1e-6 1e-6 1e-6"/>

        <geom type="sdf" name="lego_06_geom" friction="2.0 0.01 0.00001" mesh="lego"  rgba="0.9 0.6 0.1 1">
          <plugin instance="sdflego"/>
        </geom>
      </body>

    <body name="lego_07" pos="0.067 0.223 1.321">
      <freejoint/>
      <geom type="sdf" name="lego_07_geom" friction="2.0 0.01 0.00001" mesh="lego" rgba="0.5 0.5 0.1 1">
        <plugin instance="sdflego"/>
      </geom>
    </body>

    <body name="lego_08" pos="-0.045 -0.188 1.224">
      <freejoint/>
      <geom type="sdf" name="lego_08_geom" friction="2.0 0.01 0.00001" mesh="lego" rgba="0.1 0.8 0.8 1">
        <plugin instance="sdflego"/>
      </geom>
    </body>

    <body name="lego_09" pos="-0.258 0.270 1.163">
      <freejoint/>
      <geom type="sdf" name="lego_09_geom" friction="2.0 0.01 0.00001" mesh="lego" rgba="0.9 0.1 0.9 1">
        <plugin instance="sdflego"/>
      </geom>
    </body>

    <body name="lego_10" pos="0.166 0.060 1.229">
      <freejoint/>
      <geom type="sdf" name="lego_10_geom" friction="2.0 0.01 0.00001" mesh="lego" rgba="0.9 0.3 0.1 1">
        <plugin instance="sdflego"/>
      </geom>
    </body>

    <body name="lego_11" pos="0.182 -0.082 1.445">
      <freejoint/>
      <geom type="sdf" name="lego_11_geom" friction="2.0 0.01 0.00001" mesh="lego" rgba="0.9 0.6 0.1 1">
        <plugin instance="sdflego"/>
      </geom>
    </body>

    <body name="lego_12" pos="-0.199 0.156 1.435">
      <freejoint/>
      <geom type="sdf" name="lego_12_geom" friction="2.0 0.01 0.00001" mesh="lego" rgba="0.2 0.7 0.2 1">
        <plugin instance="sdflego"/>
      </geom>
    </body>

    <body name="lego_13" pos="0.018 0.198 1.176">
      <freejoint/>
      <geom type="sdf" name="lego_13_geom" friction="2.0 0.01 0.00001" mesh="lego" rgba="0.2 0.5 0.9 1">
        <plugin instance="sdflego"/>
      </geom>
    </body>

    <body name="lego_14" pos="0.146 -0.035 1.211">
      <freejoint/>
      <geom type="sdf" name="lego_14_geom" friction="2.0 0.01 0.00001" mesh="lego" rgba="0.6 0.3 0.9 1">
        <plugin instance="sdflego"/>
      </geom>
    </body>

    <body name="lego_15" pos="0.096 0.200 1.078">
      <freejoint/>
      <geom type="sdf" name="lego_15_geom" friction="2.0 0.01 0.00001" mesh="lego" rgba="0.3 0.8 0.5 1">
        <plugin instance="sdflego"/>
      </geom>
    </body>

    <body name="lego_16" pos="-0.294 -0.282 1.178">
      <freejoint/>
      <geom type="sdf" name="lego_16_geom" friction="2.0 0.01 0.00001" mesh="lego" rgba="0.8 0.2 0.5 1">
        <plugin instance="sdflego"/>
      </geom>
    </body>

    <body name="lego_17" pos="-0.069 -0.197 1.103">
      <freejoint/>
      <geom type="sdf" name="lego_17_geom" friction="2.0 0.01 0.00001" mesh="lego" rgba="0.5 0.5 0.1 1">
        <plugin instance="sdflego"/>
      </geom>
    </body>

    <body name="lego_18" pos="-0.186 -0.128 1.198">
      <freejoint/>
      <geom type="sdf" name="lego_18_geom" friction="2.0 0.01 0.00001" mesh="lego" rgba="0.1 0.8 0.8 1">
        <plugin instance="sdflego"/>
      </geom>
    </body>

    <body name="lego_19" pos="-0.093 0.012 1.282">
      <freejoint/>
      <geom type="sdf" name="lego_19_geom" friction="2.0 0.01 0.00001" mesh="lego" rgba="0.9 0.1 0.9 1">
        <plugin instance="sdflego"/>
      </geom>
    </body>

    <body name="lego_20" pos="-0.247 0.143 1.036">
      <freejoint/>
      <geom type="sdf" name="lego_20_geom" friction="2.0 0.01 0.00001" mesh="lego" rgba="0.9 0.3 0.1 1">
        <plugin instance="sdflego"/>
      </geom>
    </body>

    <body name="lego_21" pos="0.277 0.148 1.041">
      <freejoint/>
      <geom type="sdf" name="lego_21_geom" friction="2.0 0.01 0.00001" mesh="lego" rgba="0.9 0.6 0.1 1">
        <plugin instance="sdflego"/>
      </geom>
    </body>

    <body name="lego_22" pos="0.006 0.060 1.135">
      <freejoint/>
      <geom type="sdf" name="lego_22_geom" friction="2.0 0.01 0.00001" mesh="lego" rgba="0.2 0.7 0.2 1">
        <plugin instance="sdflego"/>
      </geom>
    </body>

    <body name="lego_23" pos="0.158 -0.091 1.341">
      <freejoint/>
      <geom type="sdf" name="lego_23_geom" friction="2.0 0.01 0.00001" mesh="lego" rgba="0.2 0.5 0.9 1">
        <plugin instance="sdflego"/>
      </geom>
    </body>

    <body name="lego_24" pos="0.070 0.294 1.004">
      <freejoint/>
      <geom type="sdf" name="lego_24_geom" friction="2.0 0.01 0.00001" mesh="lego" rgba="0.6 0.3 0.9 1">
        <plugin instance="sdflego"/>
      </geom>
    </body>

    <body name="lego_25" pos="0.221 -0.116 1.067">
      <freejoint/>
      <geom type="sdf" name="lego_25_geom" friction="2.0 0.01 0.00001" mesh="lego" rgba="0.3 0.8 0.5 1">
        <plugin instance="sdflego"/>
      </geom>
    </body>

    <body name="lego_26" pos="0.223 -0.162 1.360">
      <freejoint/>
      <geom type="sdf" name="lego_26_geom" friction="2.0 0.01 0.00001" mesh="lego" rgba="0.8 0.2 0.5 1">
        <plugin instance="sdflego"/>
      </geom>
    </body>

    <body name="lego_27" pos="0.155 0.030 1.191">
      <freejoint/>
      <geom type="sdf" name="lego_27_geom" friction="2.0 0.01 0.00001" mesh="lego" rgba="0.5 0.5 0.1 1">
        <plugin instance="sdflego"/>
      </geom>
    </body>

    <body name="lego_28" pos="0.064 -0.297 1.168">
      <freejoint/>
      <geom type="sdf" name="lego_28_geom" friction="2.0 0.01 0.00001" mesh="lego" rgba="0.1 0.8 0.8 1">
        <plugin instance="sdflego"/>
      </geom>
    </body>

    <body name="lego_29" pos="0.219 0.115 1.390">
      <freejoint/>
      <geom type="sdf" name="lego_29_geom" friction="2.0 0.01 0.00001" mesh="lego" rgba="0.9 0.1 0.9 1">
        <plugin instance="sdflego"/>
      </geom>
    </body>

    <body name="lego_30" pos="0.095 -0.146 1.109">
      <freejoint/>
      <geom type="sdf" name="lego_30_geom" friction="2.0 0.01 0.00001" mesh="lego" rgba="0.9 0.3 0.1 1">
        <plugin instance="sdflego"/>
      </geom>
    </body>

    <body name="lego_31" pos="0.009 -0.202 1.002">
      <freejoint/>
      <geom type="sdf" name="lego_31_geom" friction="2.0 0.01 0.00001" mesh="lego" rgba="0.9 0.6 0.1 1">
        <plugin instance="sdflego"/>
      </geom>
    </body>

    <body name="lego_32" pos="-0.016 -0.257 1.245">
      <freejoint/>
      <geom type="sdf" name="lego_32_geom" friction="2.0 0.01 0.00001" mesh="lego" rgba="0.2 0.7 0.2 1">
        <plugin instance="sdflego"/>
      </geom>
    </body>

    <body name="lego_33" pos="-0.233 -0.017 1.492">
      <freejoint/>
      <geom type="sdf" name="lego_33_geom" friction="2.0 0.01 0.00001" mesh="lego" rgba="0.2 0.5 0.9 1">
        <plugin instance="sdflego"/>
      </geom>
    </body>

    <body name="lego_34" pos="0.218 -0.201 1.304">
      <freejoint/>
      <geom type="sdf" name="lego_34_geom" friction="2.0 0.01 0.00001" mesh="lego" rgba="0.6 0.3 0.9 1">
        <plugin instance="sdflego"/>
      </geom>
    </body>

    <body name="lego_35" pos="-0.288 0.197 1.288">
      <freejoint/>
      <geom type="sdf" name="lego_35_geom" friction="2.0 0.01 0.00001" mesh="lego" rgba="0.3 0.8 0.5 1">
        <plugin instance="sdflego"/>
      </geom>
    </body>

    <body name="lego_36" pos="0.077 -0.247 1.098">
      <freejoint/>
      <geom type="sdf" name="lego_36_geom" friction="2.0 0.01 0.00001" mesh="lego" rgba="0.8 0.2 0.5 1">
        <plugin instance="sdflego"/>
      </geom>
    </body>

    <body name="lego_37" pos="0.270 0.049 1.407">
      <freejoint/>
      <geom type="sdf" name="lego_37_geom" friction="2.0 0.01 0.00001" mesh="lego" rgba="0.5 0.5 0.1 1">
        <plugin instance="sdflego"/>
      </geom>
    </body>

    <body name="lego_38" pos="-0.013 0.161 1.192">
      <freejoint/>
      <geom type="sdf" name="lego_38_geom" friction="2.0 0.01 0.00001" mesh="lego" rgba="0.1 0.8 0.8 1">
        <plugin instance="sdflego"/>
      </geom>
    </body>

    <body name="lego_39" pos="-0.172 -0.103 1.383">
      <freejoint/>
      <geom type="sdf" name="lego_39_geom" friction="2.0 0.01 0.00001" mesh="lego" rgba="0.9 0.1 0.9 1">
        <plugin instance="sdflego"/>
      </geom>
    </body>

    <body name="lego_40" pos="-0.123 -0.108 1.416">
      <freejoint/>
      <geom type="sdf" name="lego_40_geom" friction="2.0 0.01 0.00001" mesh="lego" rgba="0.9 0.3 0.1 1">
        <plugin instance="sdflego"/>
      </geom>
    </body>

    <body name="lego_41" pos="0.094 0.231 1.346">
      <freejoint/>
      <geom type="sdf" name="lego_41_geom" friction="2.0 0.01 0.00001" mesh="lego" rgba="0.9 0.6 0.1 1">
        <plugin instance="sdflego"/>
      </geom>
    </body>

    <body name="lego_42" pos="-0.163 0.245 1.333">
      <freejoint/>
      <geom type="sdf" name="lego_42_geom" friction="2.0 0.01 0.00001" mesh="lego" rgba="0.2 0.7 0.2 1">
        <plugin instance="sdflego"/>
      </geom>
    </body>

    <body name="lego_43" pos="0.231 0.165 1.222">
      <freejoint/>
      <geom type="sdf" name="lego_43_geom" friction="2.0 0.01 0.00001" mesh="lego" rgba="0.2 0.5 0.9 1">
        <plugin instance="sdflego"/>
      </geom>
    </body>

    <body name="lego_44" pos="0.145 -0.130 1.271">
      <freejoint/>
      <geom type="sdf" name="lego_44_geom" friction="2.0 0.01 0.00001" mesh="lego" rgba="0.6 0.3 0.9 1">
        <plugin instance="sdflego"/>
      </geom>
    </body>

    <body name="lego_45" pos="-0.192 0.172 1.227">
      <freejoint/>
      <geom type="sdf" name="lego_45_geom" friction="2.0 0.01 0.00001" mesh="lego" rgba="0.3 0.8 0.5 1">
        <plugin instance="sdflego"/>
      </geom>
    </body>

    <body name="lego_46" pos="-0.080 0.124 1.191">
      <freejoint/>
      <geom type="sdf" name="lego_46_geom" friction="2.0 0.01 0.00001" mesh="lego" rgba="0.8 0.2 0.5 1">
        <plugin instance="sdflego"/>
      </geom>
    </body>

    <body name="lego_47" pos="0.247 0.219 1.168">
      <freejoint/>
      <geom type="sdf" name="lego_47_geom" friction="2.0 0.01 0.00001" mesh="lego" rgba="0.5 0.5 0.1 1">
        <plugin instance="sdflego"/>
      </geom>
    </body>

    <body name="lego_48" pos="0.238 -0.235 1.003">
      <freejoint/>
      <geom type="sdf" name="lego_48_geom" friction="2.0 0.01 0.00001" mesh="lego" rgba="0.1 0.8 0.8 1">
        <plugin instance="sdflego"/>
      </geom>
    </body>

    <body name="lego_49" pos="0.176 0.113 1.229">
      <freejoint/>
      <geom type="sdf" name="lego_49_geom" friction="2.0 0.01 0.00001" mesh="lego" rgba="0.9 0.1 0.9 1">
        <plugin instance="sdflego"/>
      </geom>
    </body>

    <body name="lego_50" pos="0.236 0.234 1.376">
      <freejoint/>
      <geom type="sdf" name="lego_50_geom" friction="2.0 0.01 0.00001" mesh="lego" rgba="0.9 0.3 0.1 1">
        <plugin instance="sdflego"/>
      </geom>
    </body>

    <body name="lego_51" pos="-0.143 0.020 1.153">
      <freejoint/>
      <geom type="sdf" name="lego_51_geom" friction="2.0 0.01 0.00001" mesh="lego" rgba="0.9 0.6 0.1 1">
        <plugin instance="sdflego"/>
      </geom>
    </body>

    <body name="lego_52" pos="0.210 0.148 1.249">
      <freejoint/>
      <geom type="sdf" name="lego_52_geom" friction="2.0 0.01 0.00001" mesh="lego" rgba="0.2 0.7 0.2 1">
        <plugin instance="sdflego"/>
      </geom>
    </body>

    <body name="lego_53" pos="0.002 0.014 1.436">
      <freejoint/>
      <geom type="sdf" name="lego_53_geom" friction="2.0 0.01 0.00001" mesh="lego" rgba="0.2 0.5 0.9 1">
        <plugin instance="sdflego"/>
      </geom>
    </body>

    <body name="lego_54" pos="-0.260 -0.282 1.069">
      <freejoint/>
      <geom type="sdf" name="lego_54_geom" friction="2.0 0.01 0.00001" mesh="lego" rgba="0.6 0.3 0.9 1">
        <plugin instance="sdflego"/>
      </geom>
    </body>

    <body name="lego_55" pos="-0.067 -0.103 1.467">
      <freejoint/>
      <geom type="sdf" name="lego_55_geom" friction="2.0 0.01 0.00001" mesh="lego" rgba="0.3 0.8 0.5 1">
        <plugin instance="sdflego"/>
      </geom>
    </body>

    <body name="lego_56" pos="-0.059 -0.208 1.307">
      <freejoint/>
      <geom type="sdf" name="lego_56_geom" friction="2.0 0.01 0.00001" mesh="lego" rgba="0.8 0.2 0.5 1">
        <plugin instance="sdflego"/>
      </geom>
    </body>

    <body name="lego_57" pos="-0.078 0.281 1.425">
      <freejoint/>
      <geom type="sdf" name="lego_57_geom" friction="2.0 0.01 0.00001" mesh="lego" rgba="0.5 0.5 0.1 1">
        <plugin instance="sdflego"/>
      </geom>
    </body>

    <body name="lego_58" pos="0.176 0.022 1.330">
      <freejoint/>
      <geom type="sdf" name="lego_58_geom" friction="2.0 0.01 0.00001" mesh="lego" rgba="0.1 0.8 0.8 1">
        <plugin instance="sdflego"/>
      </geom>
    </body>

    <body name="lego_59" pos="-0.085 0.044 1.075">
      <freejoint/>
      <geom type="sdf" name="lego_59_geom" friction="2.0 0.01 0.00001" mesh="lego" rgba="0.9 0.1 0.9 1">
        <plugin instance="sdflego"/>
      </geom>
    </body>

    <body name="lego_60" pos="0.132 -0.206 1.071">
      <freejoint/>
      <geom type="sdf" name="lego_60_geom" friction="2.0 0.01 0.00001" mesh="lego" rgba="0.9 0.3 0.1 1">
        <plugin instance="sdflego"/>
      </geom>
    </body>

    <body name="lego_61" pos="-0.280 0.213 1.020">
      <freejoint/>
      <geom type="sdf" name="lego_61_geom" friction="2.0 0.01 0.00001" mesh="lego" rgba="0.9 0.6 0.1 1">
        <plugin instance="sdflego"/>
      </geom>
    </body>

    <body name="lego_62" pos="0.056 -0.032 1.274">
      <freejoint/>
      <geom type="sdf" name="lego_62_geom" friction="2.0 0.01 0.00001" mesh="lego" rgba="0.2 0.7 0.2 1">
        <plugin instance="sdflego"/>
      </geom>
    </body>

    <body name="lego_63" pos="-0.267 -0.247 1.091">
      <freejoint/>
      <geom type="sdf" name="lego_63_geom" friction="2.0 0.01 0.00001" mesh="lego" rgba="0.2 0.5 0.9 1">
        <plugin instance="sdflego"/>
      </geom>
    </body>

    <body name="lego_64" pos="0.020 0.203 1.319">
      <freejoint/>
      <geom type="sdf" name="lego_64_geom" friction="2.0 0.01 0.00001" mesh="lego" rgba="0.6 0.3 0.9 1">
        <plugin instance="sdflego"/>
      </geom>
    </body>

    <body name="lego_65" pos="-0.127 -0.288 1.207">
      <freejoint/>
      <geom type="sdf" name="lego_65_geom" friction="2.0 0.01 0.00001" mesh="lego" rgba="0.3 0.8 0.5 1">
        <plugin instance="sdflego"/>
      </geom>
    </body>

    <body name="lego_66" pos="0.124 0.210 1.116">
      <freejoint/>
      <geom type="sdf" name="lego_66_geom" friction="2.0 0.01 0.00001" mesh="lego" rgba="0.8 0.2 0.5 1">
        <plugin instance="sdflego"/>
      </geom>
    </body>

    <body name="lego_67" pos="0.197 0.209 1.021">
      <freejoint/>
      <geom type="sdf" name="lego_67_geom" friction="2.0 0.01 0.00001" mesh="lego" rgba="0.5 0.5 0.1 1">
        <plugin instance="sdflego"/>
      </geom>
    </body>

    <body name="lego_68" pos="-0.115 0.105 1.013">
      <freejoint/>
      <geom type="sdf" name="lego_68_geom" friction="2.0 0.01 0.00001" mesh="lego" rgba="0.1 0.8 0.8 1">
        <plugin instance="sdflego"/>
      </geom>
    </body>

    <body name="lego_69" pos="-0.169 -0.186 1.092">
      <freejoint/>
      <geom type="sdf" name="lego_69_geom" friction="2.0 0.01 0.00001" mesh="lego" rgba="0.9 0.1 0.9 1">
        <plugin instance="sdflego"/>
      </geom>
    </body>

    <body name="lego_70" pos="0.005 0.143 1.086">
      <freejoint/>
      <geom type="sdf" name="lego_70_geom" friction="2.0 0.01 0.00001" mesh="lego" rgba="0.9 0.3 0.1 1">
        <plugin instance="sdflego"/>
      </geom>
    </body>

    <body name="lego_71" pos="-0.265 -0.252 1.102">
      <freejoint/>
      <geom type="sdf" name="lego_71_geom" friction="2.0 0.01 0.00001" mesh="lego" rgba="0.9 0.6 0.1 1">
        <plugin instance="sdflego"/>
      </geom>
    </body>

    <body name="lego_72" pos="0.221 -0.170 1.212">
      <freejoint/>
      <geom type="sdf" name="lego_72_geom" friction="2.0 0.01 0.00001" mesh="lego" rgba="0.2 0.7 0.2 1">
        <plugin instance="sdflego"/>
      </geom>
    </body>

    <body name="lego_73" pos="-0.068 0.139 1.128">
      <freejoint/>
      <geom type="sdf" name="lego_73_geom" friction="2.0 0.01 0.00001" mesh="lego" rgba="0.2 0.5 0.9 1">
        <plugin instance="sdflego"/>
      </geom>
    </body>

    <body name="lego_74" pos="-0.215 0.005 1.409">
      <freejoint/>
      <geom type="sdf" name="lego_74_geom" friction="2.0 0.01 0.00001" mesh="lego" rgba="0.6 0.3 0.9 1">
        <plugin instance="sdflego"/>
      </geom>
    </body>

    <body name="lego_75" pos="0.150 0.017 1.244">
      <freejoint/>
      <geom type="sdf" name="lego_75_geom" friction="2.0 0.01 0.00001" mesh="lego" rgba="0.3 0.8 0.5 1">
        <plugin instance="sdflego"/>
      </geom>
    </body>

    <body name="lego_76" pos="0.254 -0.045 1.204">
      <freejoint/>
      <geom type="sdf" name="lego_76_geom" friction="2.0 0.01 0.00001" mesh="lego" rgba="0.8 0.2 0.5 1">
        <plugin instance="sdflego"/>
      </geom>
    </body>

    <body name="lego_77" pos="0.089 -0.227 1.253">
      <freejoint/>
      <geom type="sdf" name="lego_77_geom" friction="2.0 0.01 0.00001" mesh="lego" rgba="0.5 0.5 0.1 1">
        <plugin instance="sdflego"/>
      </geom>
    </body>

    <body name="lego_78" pos="0.076 -0.055 1.456">
      <freejoint/>
      <geom type="sdf" name="lego_78_geom" friction="2.0 0.01 0.00001" mesh="lego" rgba="0.1 0.8 0.8 1">
        <plugin instance="sdflego"/>
      </geom>
    </body>

    <body name="lego_79" pos="-0.058 -0.134 1.433">
      <freejoint/>
      <geom type="sdf" name="lego_79_geom" friction="2.0 0.01 0.00001" mesh="lego" rgba="0.9 0.1 0.9 1">
        <plugin instance="sdflego"/>
      </geom>
    </body>

    <body name="lego_80" pos="0.259 0.108 1.321">
      <freejoint/>
      <geom type="sdf" name="lego_80_geom" friction="2.0 0.01 0.00001" mesh="lego" rgba="0.9 0.3 0.1 1">
        <plugin instance="sdflego"/>
      </geom>
    </body>

    <body name="lego_81" pos="0.283 0.174 1.258">
      <freejoint/>
      <geom type="sdf" name="lego_81_geom" friction="2.0 0.01 0.00001" mesh="lego" rgba="0.9 0.6 0.1 1">
        <plugin instance="sdflego"/>
      </geom>
    </body>

    <body name="lego_82" pos="-0.236 -0.164 1.176">
      <freejoint/>
      <geom type="sdf" name="lego_82_geom" friction="2.0 0.01 0.00001" mesh="lego" rgba="0.2 0.7 0.2 1">
        <plugin instance="sdflego"/>
      </geom>
    </body>

    <body name="lego_83" pos="-0.001 0.137 1.401">
      <freejoint/>
      <geom type="sdf" name="lego_83_geom" friction="2.0 0.01 0.00001" mesh="lego" rgba="0.2 0.5 0.9 1">
        <plugin instance="sdflego"/>
      </geom>
    </body>

    <body name="lego_84" pos="-0.217 -0.148 1.030">
      <freejoint/>
      <geom type="sdf" name="lego_84_geom" friction="2.0 0.01 0.00001" mesh="lego" rgba="0.6 0.3 0.9 1">
        <plugin instance="sdflego"/>
      </geom>
    </body>

    <body name="lego_85" pos="-0.198 0.191 1.476">
      <freejoint/>
      <geom type="sdf" name="lego_85_geom" friction="2.0 0.01 0.00001" mesh="lego" rgba="0.3 0.8 0.5 1">
        <plugin instance="sdflego"/>
      </geom>
    </body>

    <body name="lego_86" pos="-0.077 0.049 1.423">
      <freejoint/>
      <geom type="sdf" name="lego_86_geom" friction="2.0 0.01 0.00001" mesh="lego" rgba="0.8 0.2 0.5 1">
        <plugin instance="sdflego"/>
      </geom>
    </body>

    <body name="lego_87" pos="0.196 0.211 1.148">
      <freejoint/>
      <geom type="sdf" name="lego_87_geom" friction="2.0 0.01 0.00001" mesh="lego" rgba="0.5 0.5 0.1 1">
        <plugin instance="sdflego"/>
      </geom>
    </body>

    <body name="lego_88" pos="0.259 0.285 1.329">
      <freejoint/>
      <geom type="sdf" name="lego_88_geom" friction="2.0 0.01 0.00001" mesh="lego" rgba="0.1 0.8 0.8 1">
        <plugin instance="sdflego"/>
      </geom>
    </body>

    <body name="lego_89" pos="0.129 0.190 1.423">
      <freejoint/>
      <geom type="sdf" name="lego_89_geom" friction="2.0 0.01 0.00001" mesh="lego" rgba="0.9 0.1 0.9 1">
        <plugin instance="sdflego"/>
      </geom>
    </body>

    <body name="lego_90" pos="-0.003 0.298 1.051">
      <freejoint/>
      <geom type="sdf" name="lego_90_geom" friction="2.0 0.01 0.00001" mesh="lego" rgba="0.9 0.3 0.1 1">
        <plugin instance="sdflego"/>
      </geom>
    </body>

    <body name="lego_91" pos="-0.232 0.046 1.477">
      <freejoint/>
      <geom type="sdf" name="lego_91_geom" friction="2.0 0.01 0.00001" mesh="lego" rgba="0.9 0.6 0.1 1">
        <plugin instance="sdflego"/>
      </geom>
    </body>

    <body name="lego_92" pos="-0.257 0.140 1.340">
      <freejoint/>
      <geom type="sdf" name="lego_92_geom" friction="2.0 0.01 0.00001" mesh="lego" rgba="0.2 0.7 0.2 1">
        <plugin instance="sdflego"/>
      </geom>
    </body>

    <body name="lego_93" pos="-0.094 0.209 1.407">
      <freejoint/>
      <geom type="sdf" name="lego_93_geom" friction="2.0 0.01 0.00001" mesh="lego" rgba="0.2 0.5 0.9 1">
        <plugin instance="sdflego"/>
      </geom>
    </body>

    <body name="lego_94" pos="-0.077 0.055 1.411">
      <freejoint/>
      <geom type="sdf" name="lego_94_geom" friction="2.0 0.01 0.00001" mesh="lego" rgba="0.6 0.3 0.9 1">
        <plugin instance="sdflego"/>
      </geom>
    </body>

    <body name="lego_95" pos="-0.160 -0.147 1.084">
      <freejoint/>
      <geom type="sdf" name="lego_95_geom" friction="2.0 0.01 0.00001" mesh="lego" rgba="0.3 0.8 0.5 1">
        <plugin instance="sdflego"/>
      </geom>
    </body>

    <body name="lego_96" pos="-0.237 -0.025 1.460">
      <freejoint/>
      <geom type="sdf" name="lego_96_geom" friction="2.0 0.01 0.00001" mesh="lego" rgba="0.8 0.2 0.5 1">
        <plugin instance="sdflego"/>
      </geom>
    </body>

    <body name="lego_97" pos="0.254 -0.187 1.459">
      <freejoint/>
      <geom type="sdf" name="lego_97_geom" friction="2.0 0.01 0.00001" mesh="lego" rgba="0.5 0.5 0.1 1">
        <plugin instance="sdflego"/>
      </geom>
    </body>

    <body name="lego_98" pos="0.268 0.097 1.256">
      <freejoint/>
      <geom type="sdf" name="lego_98_geom" friction="2.0 0.01 0.00001" mesh="lego" rgba="0.1 0.8 0.8 1">
        <plugin instance="sdflego"/>
      </geom>
    </body>

    <body name="lego_99" pos="0.224 0.237 1.267">
      <freejoint/>
      <geom type="sdf" name="lego_99_geom" friction="2.0 0.01 0.00001" mesh="lego" rgba="0.9 0.1 0.9 1">
        <plugin instance="sdflego"/>
      </geom>
    </body>

  </worldbody>

  <!-- 两侧手指对称 -->
  <equality>
    <joint joint1="right_joint" joint2="left_joint"/>
  </equality>

  <tendon>
    <fixed name="grasp">
      <joint joint="right_joint" coef="1"/>
      <joint joint="left_joint"  coef="1"/>
    </fixed>
  </tendon>
  <actuator>
    <motor name="left_joint" joint="left_joint" ctrllimited="true" ctrlrange="-1 1" gear="1" />
    <motor name="right_joint" joint="right_joint" ctrllimited="true" ctrlrange="-1 1" gear="1" />
    <position name="x"    joint="x" kp="800" dampratio="1" ctrlrange="-0.25 0.25"/>
    <position name="y"    joint="y" kp="800" dampratio="1" ctrlrange="-0.25 0.25"/>
    <position name="lift"  joint="lift"  kp="600" dampratio="1" ctrlrange="-0.5 0.5"/>
    <position name="rotation" joint="yaw" kp="400" dampratio="1" ctrlrange="-3.1416 3.1416"/>

  </actuator>

  <sensor>
    <actuatorpos name="left_joint_p" actuator="left_joint" />
    <actuatorvel name="left_joint_v" actuator="left_joint" />
    <actuatorfrc name="left_joint_f" actuator="left_joint" noise="0.001" />
    <actuatorpos name="right_joint_p" actuator="right_joint" />
    <actuatorvel name="right_joint_v" actuator="right_joint" />
    <actuatorfrc name="right_joint_f" actuator="right_joint" noise="0.001" />
    <framequat name="orientation" objtype="site" noise="0.001" objname="imu" />
    <gyro name="angular-velocity" site="imu" noise="0.005" cutoff="34.9" />
  </sensor>
</mujoco>

