<mujoco model="g2_eval">
  <!-- 数值较稳的物理设置 -->
  <option timestep="0.001" cone="elliptic" integrator="implicitfast"/>

  <!-- 顶层 default（唯一），命名类用嵌套 default 定义 -->
  <default>
    <joint  limited="true" damping="0.01" armature="0.01" frictionloss="0.001"/>
    <geom   condim="4" contype="1" conaffinity="15" friction="0.7 0.02 0.001" solref="0.005 1"/>
    <motor  ctrllimited="true"/>
    <equality solref="0.002 1"/>

    <!-- 可复用类：lego（给 LEGO 柔一点的接触参数） -->
    <default class="lego">
      <geom solimp="0.98 0.999 0.0001" solref="0.004 1" friction="0.8 0.02 0.001"/>
    </default>

    <!-- 可复用类：visualgeom（只做可视，避免参与碰撞） -->
    <default class="visualgeom">
      <geom material="visualgeom" condim="1" contype="0" conaffinity="0"/>
    </default>
  </default>

  <!-- sdflib（SDF 支持） -->
  <extension>
    <plugin plugin="mujoco.sdf.sdflib">
      <instance name="sdflego">
        <config key="aabb" value="0"/>
      </instance>
    </plugin>
  </extension>

  <asset>
    <!-- 夹爪三角网 -->
    <mesh name="base_link"  file="base_link.STL"/>
    <mesh name="left_link"  file="left_link.STL"/>
    <mesh name="right_link" file="right_link.STL"/>

    <!-- LEGO 网格（缩放 1cm），挂上 sdflib 插件 -->
    <mesh name="lego" file="lego.obj" scale="0.01 0.01 0.01">
      <plugin instance="sdflego"/>
    </mesh>

    <!-- 可视材质（配合 visualgeom 类） -->
    <material name="visualgeom" rgba="0.5 0.9 0.2 1"/>
  </asset>

  <worldbody>
    <!-- 地面 -->
    <geom name="ground" type="plane" size="1 1 0.02" rgba="0.8 0.8 0.8 1"
          contype="1" conaffinity="1"/>

    <!-- 夹爪平台 -->
    <body name="palm" pos="0 0 0.5">
      <joint name="x"    type="slide" axis="1 0 0" range="-0.25 0.25"/>
      <joint name="y"    type="slide" axis="0 1 0" range="-0.25 0.25"/>
      <joint name="lift" type="slide" axis="0 0 1" range="-0.5 0.50"/>
      <joint name="yaw"  type="hinge" axis="0 0 1" limited="true" range="-3.1416 3.1416"/>

      <geom type="box" size="0.1 0.1 0.01" rgba="0.2 0.2 0.8 0.2"/>

      <body name="base" pos="0 0 0" quat="0 1 0 0">
        <site name="imu" size="0.01" pos="0 0 0"/>
        <!-- 这个 geom 仅可视：使用 visualgeom 类 -->
        <geom type="mesh" mesh="base_link" class="visualgeom" rgba="0.8 0.8 0.8 1"/>

        <body name="left_link" pos="0 0 0.0635" quat="0.707105 0 -0.707108 0">
          <joint name="left_joint" pos="0 0 0" axis="0 0 1" type="slide" range="0 0.0166"/>
          <geom type="mesh" mesh="left_link" rgba="0.85 0.85 0.85 1"/>
        </body>

        <body name="right_link" pos="0 0 0.0635" quat="-2.59734e-06 0.707105 2.59735e-06 0.707108">
          <joint name="right_joint" pos="0 0 0" axis="0 0 1" type="slide" range="0 0.0166"/>
          <geom type="mesh" mesh="right_link" rgba="0.85 0.85 0.85 1"/>
        </body>
      </body>
    </body>

    <!-- 三块 LEGO：演示（需要更多就按这个样式复制） -->
    <body name="lego_00" pos="-0.10 0.00 0.02" childclass="lego">
      <freejoint/>
      <geom type="sdf" name="lego_00_geom" mesh="lego" rgba="0.9 0.3 0.1 1">
        <plugin instance="sdflego"/>
      </geom>
    </body>

    <body name="lego_01" pos="-0.06 0.02 0.02" childclass="lego">
      <freejoint/>
      <geom type="sdf" name="lego_01_geom" mesh="lego" rgba="0.2 0.7 0.2 1">
        <plugin instance="sdflego"/>
      </geom>
    </body>

    <body name="lego_02" pos="-0.02 -0.03 0.02" childclass="lego">
      <freejoint/>
      <geom type="sdf" name="lego_02_geom" mesh="lego" rgba="0.2 0.5 0.9 1">
        <plugin instance="sdflego"/>
      </geom>
    </body>
  </worldbody>

  <!-- 手指对称 -->
  <equality>
    <joint joint1="right_joint" joint2="left_joint"/>
  </equality>

  <tendon>
    <fixed name="grasp">
      <joint joint="right_joint" coef="1"/>
      <joint joint="left_joint"  coef="1"/>
    </fixed>
  </tendon>

  <!-- 与脚本一致的驱动命名 -->
  <actuator>
    <motor name="left_joint"  joint="left_joint"  ctrlrange="-1 1" gear="1"/>
    <motor name="right_joint" joint="right_joint" ctrlrange="-1 1" gear="1"/>
    <position name="x"        joint="x"    kp="800"  dampratio="1" ctrlrange="-0.25 0.25"/>
    <position name="y"        joint="y"    kp="800"  dampratio="1" ctrlrange="-0.25 0.25"/>
    <position name="lift"     joint="lift" kp="600"  dampratio="1" ctrlrange="-0.5 0.5"/>
    <position name="rotation" joint="yaw"  kp="2000" dampratio="1"
              ctrlrange="-3.1416 3.1416" forcerange="-1000 1000" gear="1"/>
  </actuator>

  <sensor>
    <actuatorpos name="left_joint_p"  actuator="left_joint"/>
    <actuatorpos name="right_joint_p" actuator="right_joint"/>
    <actuatorfrc name="left_joint_f"  actuator="left_joint"/>
    <actuatorfrc name="right_joint_f" actuator="right_joint"/>
    <framequat   name="orientation" objtype="site" objname="imu"/>
  </sensor>
</mujoco>
